<?xml version="1.0" ?>
<!-- =================================================================================== -->
<!-- |    This document was autogenerated by xacro from hanuchamp.urdf.xacro           | -->
<!-- |    EDITING THIS FILE BY HAND IS NOT RECOMMENDED                                 | -->
<!-- =================================================================================== -->
<robot name="hanuspot" xmlns:xacro="http://www.ros.org/wiki/xacro">
  <link name="hanubase">
    <visual>
      <geometry>
        <cylinder length="0.1" radius="0.05"/>
      </geometry>
    </visual>
  </link>
  <material name="black">
    <color rgba="0.15 0.15 0.15 1.0"/>
  </material>
  <link name="base_link">
    <collision>
      <origin rpy="0 0 0" xyz="0 0 0"/>
      <geometry>
        <mesh filename="package://champ_description/meshes/base.stl" scale="0.001 0.001 0.001"/>
      </geometry>
    </collision>
    <visual>
      <origin rpy="0 0 0" xyz="0 0 0"/>
      <geometry>
        <mesh filename="package://champ_description/meshes/base.stl" scale="0.001 0.001 0.001"/>
      </geometry>
      <material name="black"/>
    </visual>
  </link>
  <link name="base_inertia">
    <inertial>
      <origin xyz="0 0 0"/>
      <mass value="2.0"/>
      <inertia ixx="0.0168333333333" ixy="0.0" ixz="0.0" iyy="0.0444833333333" iyz="0.0" izz="0.0556833333333"/>
    </inertial>
  </link>
  <joint name="base_link_to_base_inertia" type="fixed">
    <parent link="base_link"/>
    <child link="base_inertia"/>
    <origin rpy="0 0 0" xyz="0 0 0"/>
  </joint>
  <!-- Adding a link to connect to Hanu robo. -->
  <joint name="spot2hanu" type="fixed">
    <origin rpy="0 0 0" xyz="0.1 0 0.05"/>
    <parent link="base_link"/>
    <child link="hanubase"/>
  </joint>
  <gazebo reference="base_link">
    <material>Gazebo/FlatBlack</material>
  </gazebo>
  <joint name="hokuyo_joint" type="fixed">
    <origin rpy="0 0 0" xyz="0.0 0.0 0.105"/>
    <parent link="base_link"/>
    <child link="hokuyo_frame"/>
  </joint>
  <link name="hokuyo_frame">
    <inertial>
      <mass value="0.270"/>
      <origin rpy="0 0 0" xyz="0 0 0"/>
      <inertia ixx="2.632e-4" ixy="0" ixz="0" iyy="2.632e-4" iyz="0" izz="1.62e-4"/>
    </inertial>
    <visual>
      <origin rpy="0 0 0" xyz="0 0 0"/>
      <geometry>
        <mesh filename="package://hector_sensors_description/meshes/hokuyo_utm30lx/hokuyo_utm_30lx.dae"/>
      </geometry>
    </visual>
    <collision>
      <origin rpy="0 0 0" xyz="0 0 -0.0115"/>
      <geometry>
        <box size="0.058 0.058 0.087"/>
        <!--<mesh filename="package://hector_sensors_description/meshes/hokuyo_utm30lx/hokuyo_utm_30lx.stl"/>-->
      </geometry>
    </collision>
  </link>
  <gazebo reference="hokuyo_frame">
    <sensor name="hokuyo" type="ray">
      <always_on>true</always_on>
      <update_rate>30</update_rate>
      <pose>0 0 0 0 0 0</pose>
      <visualize>false</visualize>
      <ray>
        <scan>
          <horizontal>
            <samples>1040</samples>
            <resolution>1</resolution>
            <min_angle>2.26892802759</min_angle>
            <max_angle>-2.26892802759</max_angle>
          </horizontal>
        </scan>
        <range>
          <min>0.08</min>
          <max>30.0</max>
          <resolution>0.01</resolution>
        </range>
        <noise>
          <type>gaussian</type>
          <mean>0.0</mean>
          <stddev>0.004</stddev>
        </noise>
      </ray>
      <plugin filename="libgazebo_ros_laser.so" name="gazebo_ros_hokuyo_controller">
        <topicName>scan</topicName>
        <frameName>hokuyo_frame</frameName>
      </plugin>
    </sensor>
  </gazebo>
  <joint name="camera_joint" type="fixed">
    <origin rpy="0 0 0" xyz="0.25 0.0 -0.075"/>
    <parent link="base_link"/>
    <child link="camera_link"/>
  </joint>
  <link name="camera_link">
    <inertial>
      <mass value="0.200"/>
      <origin rpy="0 0 0" xyz="0 0 0"/>
      <inertia ixx="5.8083e-4" ixy="0" ixz="0" iyy="3.0833e-5" iyz="0" izz="5.9083e-4"/>
    </inertial>
    <visual>
      <origin rpy="0 0 0" xyz="0 0 0"/>
      <geometry>
        <mesh filename="package://hector_sensors_description/meshes/asus_camera/asus_camera_simple.dae"/>
      </geometry>
    </visual>
    <!--        
       <collision>
          <origin xyz="0 0 0" rpy="0 0 0" />
          <geometry>
            <box size="0.035 0.185 0.025"/>
          </geometry>
        </collision>
        -->
    <collision>
      <origin rpy="0 0 0" xyz="0 0 0"/>
      <geometry>
        <mesh filename="package://hector_sensors_description/meshes/asus_camera/asus_camera_simple.dae"/>
      </geometry>
    </collision>
  </link>
  <joint name="camera_depth_joint" type="fixed">
    <origin rpy="0 0 0" xyz="0.0 0.049 0.0"/>
    <parent link="camera_link"/>
    <child link="camera_depth_frame"/>
  </joint>
  <link name="camera_depth_frame"/>
  <joint name="camera_depth_optical_joint" type="fixed">
    <origin rpy="-1.57079632679 0.0 -1.57079632679" xyz="0 0 0"/>
    <parent link="camera_depth_frame"/>
    <child link="camera_depth_optical_frame"/>
  </joint>
  <link name="camera_depth_optical_frame"/>
  <joint name="camera_rgb_joint" type="fixed">
    <origin rpy="0 0 0" xyz="0.0 0.022 0.0"/>
    <parent link="camera_link"/>
    <child link="camera_rgb_frame"/>
  </joint>
  <link name="camera_rgb_frame"/>
  <joint name="camera_rgb_optical_joint" type="fixed">
    <origin rpy="-1.57079632679 0.0 -1.57079632679" xyz="0 0 0"/>
    <parent link="camera_rgb_frame"/>
    <child link="camera_rgb_optical_frame"/>
  </joint>
  <link name="camera_rgb_optical_frame"/>
  <!-- ASUS Xtion PRO camera for simulation -->
  <gazebo reference="camera_depth_frame">
    <sensor name="camera" type="depth">
      <update_rate>20</update_rate>
      <camera>
        <horizontal_fov>1.09606677025</horizontal_fov>
        <image>
          <format>R8G8B8</format>
          <width>640</width>
          <height>480</height>
        </image>
        <clip>
          <near>0.5</near>
          <far>9</far>
        </clip>
      </camera>
      <plugin filename="libgazebo_ros_openni_kinect.so" name="camera_camera_controller">
        <imageTopicName>camera/rgb/image_raw</imageTopicName>
        <cameraInfoTopicName>camera/rgb/camera_info</cameraInfoTopicName>
        <depthImageTopicName>camera/depth/image_raw</depthImageTopicName>
        <depthImageCameraInfoTopicName>camera/depth/camera_info</depthImageCameraInfoTopicName>
        <pointCloudTopicName>camera/depth/points</pointCloudTopicName>
        <frameName>camera_depth_optical_frame</frameName>
      </plugin>
    </sensor>
  </gazebo>
  <gazebo>
    <plugin filename="libhector_gazebo_ros_imu.so" name="imu_controller">
      <updateRate>50.0</updateRate>
      <bodyName>imu_link</bodyName>
      <topicName>imu/data</topicName>
      <accelDrift>0.005 0.005 0.005</accelDrift>
      <accelGaussianNoise>0.005 0.005 0.005</accelGaussianNoise>
      <rateDrift>0.005 0.005 0.005 </rateDrift>
      <rateGaussianNoise>0.005 0.005 0.005 </rateGaussianNoise>
      <headingDrift>0.005</headingDrift>
      <headingGaussianNoise>0.005</headingGaussianNoise>
    </plugin>
  </gazebo>
  <link name="imu_link">
    <inertial>
      <mass value="0.001"/>
      <origin rpy="0 0 0" xyz="0 0 0"/>
      <inertia ixx="1e-09" ixy="0.0" ixz="0.0" iyy="1e-09" iyz="0.0" izz="1e-09"/>
    </inertial>
  </link>
  <joint name="imu_joint" type="fixed">
    <parent link="base_link"/>
    <child link="imu_link"/>
  </joint>
  <!-- <xacro:include filename="$(find velodyne_description)/urdf/VLP-16.urdf.xacro"/>
        <xacro:VLP-16 parent="${base_name}" name="velodyne" topic="velodyne_points" hz="10" samples="1024" gpu="false" lasers="16" max_range="100">
            <origin xyz="0 0 ${base_height / 2}" rpy="0 0 0" />
        </xacro:VLP-16>

        <xacro:include filename="$(find champ_arm_description)/urdf/champ_arm.urdf.xacro" />
        <xacro:champ_arm parent="${base_name}">
            <origin xyz="0.07 0.0 ${base_height / 2}" rpy="0 0 0"/>
        </xacro:champ_arm> -->
  <link name="lf_hip_debug_link"/>
  <link name="lf_hip_link">
    <inertial>
      <mass value="0.25"/>
      <inertia ixx="0.000485416666667" ixy="0.0" ixz="0.0" iyy="0.000613416666667" iyz="0.0" izz="0.000394666666667"/>
    </inertial>
    <collision>
      <origin rpy="0 0 0" xyz="0 0 0"/>
      <geometry>
        <mesh filename="package://champ_description/meshes/hip.stl" scale="0.001 0.001 0.001"/>
      </geometry>
    </collision>
    <visual>
      <origin rpy="0 0 0" xyz="0 0 0"/>
      <geometry>
        <mesh filename="package://champ_description/meshes/hip.stl" scale="0.001 0.001 0.001"/>
      </geometry>
      <material name="black"/>
    </visual>
  </link>
  <gazebo reference="lf_hip_link">
    <material>Gazebo/FlatBlack</material>
  </gazebo>
  <link name="lf_upper_leg_link">
    <inertial>
      <origin xyz="0 0 -0.0705"/>
      <mass value="0.125"/>
      <inertia ixx="0.0003873984375" ixy="0.0" ixz="0.0" iyy="0.000404065104167" iyz="0.0" izz="3.54166666667e-05"/>
    </inertial>
    <collision>
      <origin rpy="0 0 0" xyz="0 0 0"/>
      <geometry>
        <mesh filename="package://champ_description/meshes/upper_leg.stl" scale="0.001 0.001 0.001"/>
      </geometry>
    </collision>
    <visual>
      <origin rpy="0 0 0" xyz="0 0 0"/>
      <geometry>
        <mesh filename="package://champ_description/meshes/upper_leg.stl" scale="0.001 0.001 0.001"/>
      </geometry>
      <material name="black"/>
    </visual>
  </link>
  <gazebo reference="lf_upper_leg_link">
    <material>Gazebo/FlatBlack</material>
  </gazebo>
  <link name="lf_lower_leg_link">
    <inertial>
      <origin xyz="0 0 -0.063"/>
      <mass value="0.125"/>
      <inertia ixx="0.000258541666667" ixy="0.0" ixz="0.0" iyy="0.00026934375" iyz="0.0" izz="2.08854166667e-05"/>
    </inertial>
    <collision>
      <origin rpy="0 0 0" xyz="0 0 0"/>
      <geometry>
        <mesh filename="package://champ_description/meshes/lower_leg.stl" scale="0.001 0.001 0.001"/>
      </geometry>
    </collision>
    <visual>
      <origin rpy="0 0 0" xyz="0 0 0"/>
      <geometry>
        <mesh filename="package://champ_description/meshes/lower_leg.stl" scale="0.001 0.001 0.001"/>
      </geometry>
      <material name="black"/>
    </visual>
  </link>
  <gazebo reference="lf_lower_leg_link">
    <kp>1000000.0</kp>
    <kd>1.0</kd>
    <mu1>0.8</mu1>
    <mu2>0.8</mu2>
    <maxVel>0.0</maxVel>
    <minDepth>0.001</minDepth>
    <material>Gazebo/FlatBlack</material>
  </gazebo>
  <link name="lf_foot_link"/>
  <joint name="lf_debug_joint" type="fixed">
    <parent link="base_link"/>
    <child link="lf_hip_debug_link"/>
    <origin rpy="0 0 0" xyz="0.175 0.105 0"/>
  </joint>
  <joint name="lf_hip_joint" type="revolute">
    <axis xyz="1 0 0"/>
    <limit effort="25" lower="-3.14159265359" upper="3.14159265359" velocity="1.5"/>
    <parent link="base_link"/>
    <child link="lf_hip_link"/>
    <origin rpy="0 0 0" xyz="0.175 0.105 0"/>
  </joint>
  <joint name="lf_upper_leg_joint" type="revolute">
    <axis xyz="0 1 0"/>
    <limit effort="25" lower="-3.14159265359" upper="3.14159265359" velocity="1.5"/>
    <parent link="lf_hip_link"/>
    <child link="lf_upper_leg_link"/>
    <origin rpy="0 0 0" xyz="0 0.06 0"/>
  </joint>
  <joint name="lf_lower_leg_joint" type="revolute">
    <axis xyz="0 1 0"/>
    <limit effort="25" lower="-3.14159265359" upper="3.14159265359" velocity="1.5"/>
    <parent link="lf_upper_leg_link"/>
    <child link="lf_lower_leg_link"/>
    <origin rpy="0 0 0" xyz="0 0 -0.141"/>
  </joint>
  <joint name="lf_foot_joint" type="fixed">
    <parent link="lf_lower_leg_link"/>
    <child link="lf_foot_link"/>
    <!-- <origin xyz="0.00325 0 -${lower_leg_to_foot_distance}" rpy="0 0 0" /> -->
    <origin rpy="0 0 0" xyz="0 0 -0.141"/>
  </joint>
  <transmission name="lf_hip_joint_trans">
    <type>transmission_interface/SimpleTransmission</type>
    <joint name="lf_hip_joint">
      <hardwareInterface>hardware_interface/EffortJointInterface</hardwareInterface>
    </joint>
    <actuator name="lf_hip_joint_motor">
      <hardwareInterface>hardware_interface/EffortJointInterface</hardwareInterface>
      <mechanicalReduction>1</mechanicalReduction>
    </actuator>
  </transmission>
  <transmission name="lf_upper_leg_joint_trans">
    <type>transmission_interface/SimpleTransmission</type>
    <joint name="lf_upper_leg_joint">
      <hardwareInterface>hardware_interface/EffortJointInterface</hardwareInterface>
    </joint>
    <actuator name="lf_upper_leg_joint_motor">
      <hardwareInterface>hardware_interface/EffortJointInterface</hardwareInterface>
      <mechanicalReduction>1</mechanicalReduction>
    </actuator>
  </transmission>
  <transmission name="lf_lower_leg_joint_trans">
    <type>transmission_interface/SimpleTransmission</type>
    <joint name="lf_lower_leg_joint">
      <hardwareInterface>hardware_interface/EffortJointInterface</hardwareInterface>
    </joint>
    <actuator name="lf_lower_joint_motor">
      <hardwareInterface>hardware_interface/EffortJointInterface</hardwareInterface>
      <mechanicalReduction>1</mechanicalReduction>
    </actuator>
  </transmission>
  <link name="lh_hip_debug_link"/>
  <link name="lh_hip_link">
    <inertial>
      <mass value="0.25"/>
      <inertia ixx="0.000485416666667" ixy="0.0" ixz="0.0" iyy="0.000613416666667" iyz="0.0" izz="0.000394666666667"/>
    </inertial>
    <collision>
      <origin rpy="0 0 0" xyz="0 0 0"/>
      <geometry>
        <mesh filename="package://champ_description/meshes/hip.stl" scale="0.001 0.001 0.001"/>
      </geometry>
    </collision>
    <visual>
      <origin rpy="0 0 0" xyz="0 0 0"/>
      <geometry>
        <mesh filename="package://champ_description/meshes/hip.stl" scale="0.001 0.001 0.001"/>
      </geometry>
      <material name="black"/>
    </visual>
  </link>
  <gazebo reference="lh_hip_link">
    <material>Gazebo/FlatBlack</material>
  </gazebo>
  <link name="lh_upper_leg_link">
    <inertial>
      <origin xyz="0 0 -0.0705"/>
      <mass value="0.125"/>
      <inertia ixx="0.0003873984375" ixy="0.0" ixz="0.0" iyy="0.000404065104167" iyz="0.0" izz="3.54166666667e-05"/>
    </inertial>
    <collision>
      <origin rpy="0 0 0" xyz="0 0 0"/>
      <geometry>
        <mesh filename="package://champ_description/meshes/upper_leg.stl" scale="0.001 0.001 0.001"/>
      </geometry>
    </collision>
    <visual>
      <origin rpy="0 0 0" xyz="0 0 0"/>
      <geometry>
        <mesh filename="package://champ_description/meshes/upper_leg.stl" scale="0.001 0.001 0.001"/>
      </geometry>
      <material name="black"/>
    </visual>
  </link>
  <gazebo reference="lh_upper_leg_link">
    <material>Gazebo/FlatBlack</material>
  </gazebo>
  <link name="lh_lower_leg_link">
    <inertial>
      <origin xyz="0 0 -0.063"/>
      <mass value="0.125"/>
      <inertia ixx="0.000258541666667" ixy="0.0" ixz="0.0" iyy="0.00026934375" iyz="0.0" izz="2.08854166667e-05"/>
    </inertial>
    <collision>
      <origin rpy="0 0 0" xyz="0 0 0"/>
      <geometry>
        <mesh filename="package://champ_description/meshes/lower_leg.stl" scale="0.001 0.001 0.001"/>
      </geometry>
    </collision>
    <visual>
      <origin rpy="0 0 0" xyz="0 0 0"/>
      <geometry>
        <mesh filename="package://champ_description/meshes/lower_leg.stl" scale="0.001 0.001 0.001"/>
      </geometry>
      <material name="black"/>
    </visual>
  </link>
  <gazebo reference="lh_lower_leg_link">
    <kp>1000000.0</kp>
    <kd>1.0</kd>
    <mu1>0.8</mu1>
    <mu2>0.8</mu2>
    <maxVel>0.0</maxVel>
    <minDepth>0.001</minDepth>
    <material>Gazebo/FlatBlack</material>
  </gazebo>
  <link name="lh_foot_link"/>
  <joint name="lh_debug_joint" type="fixed">
    <parent link="base_link"/>
    <child link="lh_hip_debug_link"/>
    <origin rpy="0 0 0" xyz="-0.175 0.105 0"/>
  </joint>
  <joint name="lh_hip_joint" type="revolute">
    <axis xyz="1 0 0"/>
    <limit effort="25" lower="-3.14159265359" upper="3.14159265359" velocity="1.5"/>
    <parent link="base_link"/>
    <child link="lh_hip_link"/>
    <origin rpy="0 0 0" xyz="-0.175 0.105 0"/>
  </joint>
  <joint name="lh_upper_leg_joint" type="revolute">
    <axis xyz="0 1 0"/>
    <limit effort="25" lower="-3.14159265359" upper="3.14159265359" velocity="1.5"/>
    <parent link="lh_hip_link"/>
    <child link="lh_upper_leg_link"/>
    <origin rpy="0 0 0" xyz="0 0.06 0"/>
  </joint>
  <joint name="lh_lower_leg_joint" type="revolute">
    <axis xyz="0 1 0"/>
    <limit effort="25" lower="-3.14159265359" upper="3.14159265359" velocity="1.5"/>
    <parent link="lh_upper_leg_link"/>
    <child link="lh_lower_leg_link"/>
    <origin rpy="0 0 0" xyz="0 0 -0.141"/>
  </joint>
  <joint name="lh_foot_joint" type="fixed">
    <parent link="lh_lower_leg_link"/>
    <child link="lh_foot_link"/>
    <!-- <origin xyz="0.00325 0 -${lower_leg_to_foot_distance}" rpy="0 0 0" /> -->
    <origin rpy="0 0 0" xyz="0 0 -0.141"/>
  </joint>
  <transmission name="lh_hip_joint_trans">
    <type>transmission_interface/SimpleTransmission</type>
    <joint name="lh_hip_joint">
      <hardwareInterface>hardware_interface/EffortJointInterface</hardwareInterface>
    </joint>
    <actuator name="lh_hip_joint_motor">
      <hardwareInterface>hardware_interface/EffortJointInterface</hardwareInterface>
      <mechanicalReduction>1</mechanicalReduction>
    </actuator>
  </transmission>
  <transmission name="lh_upper_leg_joint_trans">
    <type>transmission_interface/SimpleTransmission</type>
    <joint name="lh_upper_leg_joint">
      <hardwareInterface>hardware_interface/EffortJointInterface</hardwareInterface>
    </joint>
    <actuator name="lh_upper_leg_joint_motor">
      <hardwareInterface>hardware_interface/EffortJointInterface</hardwareInterface>
      <mechanicalReduction>1</mechanicalReduction>
    </actuator>
  </transmission>
  <transmission name="lh_lower_leg_joint_trans">
    <type>transmission_interface/SimpleTransmission</type>
    <joint name="lh_lower_leg_joint">
      <hardwareInterface>hardware_interface/EffortJointInterface</hardwareInterface>
    </joint>
    <actuator name="lh_lower_joint_motor">
      <hardwareInterface>hardware_interface/EffortJointInterface</hardwareInterface>
      <mechanicalReduction>1</mechanicalReduction>
    </actuator>
  </transmission>
  <link name="rf_hip_debug_link"/>
  <link name="rf_hip_link">
    <inertial>
      <mass value="0.25"/>
      <inertia ixx="0.000485416666667" ixy="0.0" ixz="0.0" iyy="0.000613416666667" iyz="0.0" izz="0.000394666666667"/>
    </inertial>
    <collision>
      <origin rpy="0 0 0" xyz="0 0 0"/>
      <geometry>
        <mesh filename="package://champ_description/meshes/hip.stl" scale="0.001 0.001 0.001"/>
      </geometry>
    </collision>
    <visual>
      <origin rpy="0 0 0" xyz="0 0 0"/>
      <geometry>
        <mesh filename="package://champ_description/meshes/hip.stl" scale="0.001 0.001 0.001"/>
      </geometry>
      <material name="black"/>
    </visual>
  </link>
  <gazebo reference="rf_hip_link">
    <material>Gazebo/FlatBlack</material>
  </gazebo>
  <link name="rf_upper_leg_link">
    <inertial>
      <origin xyz="0 0 -0.0705"/>
      <mass value="0.125"/>
      <inertia ixx="0.0003873984375" ixy="0.0" ixz="0.0" iyy="0.000404065104167" iyz="0.0" izz="3.54166666667e-05"/>
    </inertial>
    <collision>
      <origin rpy="0 0 0" xyz="0 0 0"/>
      <geometry>
        <mesh filename="package://champ_description/meshes/upper_leg.stl" scale="0.001 0.001 0.001"/>
      </geometry>
    </collision>
    <visual>
      <origin rpy="0 0 0" xyz="0 0 0"/>
      <geometry>
        <mesh filename="package://champ_description/meshes/upper_leg.stl" scale="0.001 0.001 0.001"/>
      </geometry>
      <material name="black"/>
    </visual>
  </link>
  <gazebo reference="rf_upper_leg_link">
    <material>Gazebo/FlatBlack</material>
  </gazebo>
  <link name="rf_lower_leg_link">
    <inertial>
      <origin xyz="0 0 -0.063"/>
      <mass value="0.125"/>
      <inertia ixx="0.000258541666667" ixy="0.0" ixz="0.0" iyy="0.00026934375" iyz="0.0" izz="2.08854166667e-05"/>
    </inertial>
    <collision>
      <origin rpy="0 0 0" xyz="0 0 0"/>
      <geometry>
        <mesh filename="package://champ_description/meshes/lower_leg.stl" scale="0.001 0.001 0.001"/>
      </geometry>
    </collision>
    <visual>
      <origin rpy="0 0 0" xyz="0 0 0"/>
      <geometry>
        <mesh filename="package://champ_description/meshes/lower_leg.stl" scale="0.001 0.001 0.001"/>
      </geometry>
      <material name="black"/>
    </visual>
  </link>
  <gazebo reference="rf_lower_leg_link">
    <kp>1000000.0</kp>
    <kd>1.0</kd>
    <mu1>0.8</mu1>
    <mu2>0.8</mu2>
    <maxVel>0.0</maxVel>
    <minDepth>0.001</minDepth>
    <material>Gazebo/FlatBlack</material>
  </gazebo>
  <link name="rf_foot_link"/>
  <joint name="rf_debug_joint" type="fixed">
    <parent link="base_link"/>
    <child link="rf_hip_debug_link"/>
    <origin rpy="0 0 0" xyz="0.175 -0.105 0"/>
  </joint>
  <joint name="rf_hip_joint" type="revolute">
    <axis xyz="1 0 0"/>
    <limit effort="25" lower="-3.14159265359" upper="3.14159265359" velocity="1.5"/>
    <parent link="base_link"/>
    <child link="rf_hip_link"/>
    <origin rpy="0 0 0" xyz="0.175 -0.105 0"/>
  </joint>
  <joint name="rf_upper_leg_joint" type="revolute">
    <axis xyz="0 1 0"/>
    <limit effort="25" lower="-3.14159265359" upper="3.14159265359" velocity="1.5"/>
    <parent link="rf_hip_link"/>
    <child link="rf_upper_leg_link"/>
    <origin rpy="0 0 0" xyz="0 -0.06 0"/>
  </joint>
  <joint name="rf_lower_leg_joint" type="revolute">
    <axis xyz="0 1 0"/>
    <limit effort="25" lower="-3.14159265359" upper="3.14159265359" velocity="1.5"/>
    <parent link="rf_upper_leg_link"/>
    <child link="rf_lower_leg_link"/>
    <origin rpy="0 0 0" xyz="0 0 -0.141"/>
  </joint>
  <joint name="rf_foot_joint" type="fixed">
    <parent link="rf_lower_leg_link"/>
    <child link="rf_foot_link"/>
    <!-- <origin xyz="0.00325 0 -${lower_leg_to_foot_distance}" rpy="0 0 0" /> -->
    <origin rpy="0 0 0" xyz="0 0 -0.141"/>
  </joint>
  <transmission name="rf_hip_joint_trans">
    <type>transmission_interface/SimpleTransmission</type>
    <joint name="rf_hip_joint">
      <hardwareInterface>hardware_interface/EffortJointInterface</hardwareInterface>
    </joint>
    <actuator name="rf_hip_joint_motor">
      <hardwareInterface>hardware_interface/EffortJointInterface</hardwareInterface>
      <mechanicalReduction>1</mechanicalReduction>
    </actuator>
  </transmission>
  <transmission name="rf_upper_leg_joint_trans">
    <type>transmission_interface/SimpleTransmission</type>
    <joint name="rf_upper_leg_joint">
      <hardwareInterface>hardware_interface/EffortJointInterface</hardwareInterface>
    </joint>
    <actuator name="rf_upper_leg_joint_motor">
      <hardwareInterface>hardware_interface/EffortJointInterface</hardwareInterface>
      <mechanicalReduction>1</mechanicalReduction>
    </actuator>
  </transmission>
  <transmission name="rf_lower_leg_joint_trans">
    <type>transmission_interface/SimpleTransmission</type>
    <joint name="rf_lower_leg_joint">
      <hardwareInterface>hardware_interface/EffortJointInterface</hardwareInterface>
    </joint>
    <actuator name="rf_lower_joint_motor">
      <hardwareInterface>hardware_interface/EffortJointInterface</hardwareInterface>
      <mechanicalReduction>1</mechanicalReduction>
    </actuator>
  </transmission>
  <link name="rh_hip_debug_link"/>
  <link name="rh_hip_link">
    <inertial>
      <mass value="0.25"/>
      <inertia ixx="0.000485416666667" ixy="0.0" ixz="0.0" iyy="0.000613416666667" iyz="0.0" izz="0.000394666666667"/>
    </inertial>
    <collision>
      <origin rpy="0 0 0" xyz="0 0 0"/>
      <geometry>
        <mesh filename="package://champ_description/meshes/hip.stl" scale="0.001 0.001 0.001"/>
      </geometry>
    </collision>
    <visual>
      <origin rpy="0 0 0" xyz="0 0 0"/>
      <geometry>
        <mesh filename="package://champ_description/meshes/hip.stl" scale="0.001 0.001 0.001"/>
      </geometry>
      <material name="black"/>
    </visual>
  </link>
  <gazebo reference="rh_hip_link">
    <material>Gazebo/FlatBlack</material>
  </gazebo>
  <link name="rh_upper_leg_link">
    <inertial>
      <origin xyz="0 0 -0.0705"/>
      <mass value="0.125"/>
      <inertia ixx="0.0003873984375" ixy="0.0" ixz="0.0" iyy="0.000404065104167" iyz="0.0" izz="3.54166666667e-05"/>
    </inertial>
    <collision>
      <origin rpy="0 0 0" xyz="0 0 0"/>
      <geometry>
        <mesh filename="package://champ_description/meshes/upper_leg.stl" scale="0.001 0.001 0.001"/>
      </geometry>
    </collision>
    <visual>
      <origin rpy="0 0 0" xyz="0 0 0"/>
      <geometry>
        <mesh filename="package://champ_description/meshes/upper_leg.stl" scale="0.001 0.001 0.001"/>
      </geometry>
      <material name="black"/>
    </visual>
  </link>
  <gazebo reference="rh_upper_leg_link">
    <material>Gazebo/FlatBlack</material>
  </gazebo>
  <link name="rh_lower_leg_link">
    <inertial>
      <origin xyz="0 0 -0.063"/>
      <mass value="0.125"/>
      <inertia ixx="0.000258541666667" ixy="0.0" ixz="0.0" iyy="0.00026934375" iyz="0.0" izz="2.08854166667e-05"/>
    </inertial>
    <collision>
      <origin rpy="0 0 0" xyz="0 0 0"/>
      <geometry>
        <mesh filename="package://champ_description/meshes/lower_leg.stl" scale="0.001 0.001 0.001"/>
      </geometry>
    </collision>
    <visual>
      <origin rpy="0 0 0" xyz="0 0 0"/>
      <geometry>
        <mesh filename="package://champ_description/meshes/lower_leg.stl" scale="0.001 0.001 0.001"/>
      </geometry>
      <material name="black"/>
    </visual>
  </link>
  <gazebo reference="rh_lower_leg_link">
    <kp>1000000.0</kp>
    <kd>1.0</kd>
    <mu1>0.8</mu1>
    <mu2>0.8</mu2>
    <maxVel>0.0</maxVel>
    <minDepth>0.001</minDepth>
    <material>Gazebo/FlatBlack</material>
  </gazebo>
  <link name="rh_foot_link"/>
  <joint name="rh_debug_joint" type="fixed">
    <parent link="base_link"/>
    <child link="rh_hip_debug_link"/>
    <origin rpy="0 0 0" xyz="-0.175 -0.105 0"/>
  </joint>
  <joint name="rh_hip_joint" type="revolute">
    <axis xyz="1 0 0"/>
    <limit effort="25" lower="-3.14159265359" upper="3.14159265359" velocity="1.5"/>
    <parent link="base_link"/>
    <child link="rh_hip_link"/>
    <origin rpy="0 0 0" xyz="-0.175 -0.105 0"/>
  </joint>
  <joint name="rh_upper_leg_joint" type="revolute">
    <axis xyz="0 1 0"/>
    <limit effort="25" lower="-3.14159265359" upper="3.14159265359" velocity="1.5"/>
    <parent link="rh_hip_link"/>
    <child link="rh_upper_leg_link"/>
    <origin rpy="0 0 0" xyz="0 -0.06 0"/>
  </joint>
  <joint name="rh_lower_leg_joint" type="revolute">
    <axis xyz="0 1 0"/>
    <limit effort="25" lower="-3.14159265359" upper="3.14159265359" velocity="1.5"/>
    <parent link="rh_upper_leg_link"/>
    <child link="rh_lower_leg_link"/>
    <origin rpy="0 0 0" xyz="0 0 -0.141"/>
  </joint>
  <joint name="rh_foot_joint" type="fixed">
    <parent link="rh_lower_leg_link"/>
    <child link="rh_foot_link"/>
    <!-- <origin xyz="0.00325 0 -${lower_leg_to_foot_distance}" rpy="0 0 0" /> -->
    <origin rpy="0 0 0" xyz="0 0 -0.141"/>
  </joint>
  <transmission name="rh_hip_joint_trans">
    <type>transmission_interface/SimpleTransmission</type>
    <joint name="rh_hip_joint">
      <hardwareInterface>hardware_interface/EffortJointInterface</hardwareInterface>
    </joint>
    <actuator name="rh_hip_joint_motor">
      <hardwareInterface>hardware_interface/EffortJointInterface</hardwareInterface>
      <mechanicalReduction>1</mechanicalReduction>
    </actuator>
  </transmission>
  <transmission name="rh_upper_leg_joint_trans">
    <type>transmission_interface/SimpleTransmission</type>
    <joint name="rh_upper_leg_joint">
      <hardwareInterface>hardware_interface/EffortJointInterface</hardwareInterface>
    </joint>
    <actuator name="rh_upper_leg_joint_motor">
      <hardwareInterface>hardware_interface/EffortJointInterface</hardwareInterface>
      <mechanicalReduction>1</mechanicalReduction>
    </actuator>
  </transmission>
  <transmission name="rh_lower_leg_joint_trans">
    <type>transmission_interface/SimpleTransmission</type>
    <joint name="rh_lower_leg_joint">
      <hardwareInterface>hardware_interface/EffortJointInterface</hardwareInterface>
    </joint>
    <actuator name="rh_lower_joint_motor">
      <hardwareInterface>hardware_interface/EffortJointInterface</hardwareInterface>
      <mechanicalReduction>1</mechanicalReduction>
    </actuator>
  </transmission>
  <gazebo>
    <plugin filename="libgazebo_ros_p3d.so" name="p3d_base_controller">
      <alwaysOn>true</alwaysOn>
      <updateRate>10.0</updateRate>
      <bodyName>base_link</bodyName>
      <topicName>odom/ground_truth</topicName>
      <gaussianNoise>0.01</gaussianNoise>
      <frameName>world</frameName>
      <xyzOffsets>0 0 0</xyzOffsets>
      <rpyOffsets>0 0 0</rpyOffsets>
    </plugin>
  </gazebo>
  <gazebo>
    <plugin filename="libgazebo_ros_control.so" name="gazebo_ros_control">
      <legacyModeNS>true</legacyModeNS>
    </plugin>
  </gazebo>
  <link name="pedestal"/>
  <joint name="hanu2reachy" type="fixed">
    <origin rpy="0 0 0" xyz="0.0 0 0"/>
    <parent link="hanubase"/>
    <child link="pedestal"/>
  </joint>
  <!-- Torso Link -->
  <link name="torso">
    <inertial>
      <origin rpy="0.0 0.0 0.0" xyz="0.0 0.019 -0.009"/>
      <mass value="0.527"/>
      <inertia ixx="2.89598e-3" ixy="-1.16791e-6" ixz="-8.28749e-6" iyy="4.491e-3" iyz="2.343e-4" izz="3.995e-3"/>
    </inertial>
    <visual name="">
      <origin rpy="0.0 0.0 0.0" xyz="0.0 0.0 0.0"/>
      <geometry>
        <mesh filename="package://reachy_description/meshes/torso.dae"/>
      </geometry>
    </visual>
    <collision>
      <origin rpy="0 0.05 0" xyz="0 0 -0.1"/>
      <geometry>
        <box size="0.11 0.2 0.32"/>
      </geometry>
    </collision>
  </link>
  <!-- Head Links -->
  <link name="head">
    <inertial>
      <origin rpy="0.0 0.0 0.0" xyz="-0.009 -0.002 0.059"/>
      <mass value="0.237"/>
      <inertia ixx="1.676e-3" ixy="3.068e-6" ixz="1.2449e-4" iyy="1.368e-3" iyz="3.360e-5" izz="8.425e-4"/>
    </inertial>
    <visual name="">
      <origin rpy="0.0 0.0 0.0" xyz="0.0 0.0 0.0"/>
      <geometry>
        <mesh filename="package://reachy_description/meshes/head.dae"/>
      </geometry>
    </visual>
    <collision>
      <origin rpy="1.57 0.0 0.0" xyz="-0.009 -0.002 0.059"/>
      <geometry>
        <cylinder length="0.15" radius="0.06"/>
      </geometry>
    </collision>
  </link>
  <link name="l_antenna">
    <inertial>
      <origin rpy="0.0 0.0 0.0" xyz="-0.001 0.0 0.008"/>
      <mass value="0.004"/>
      <inertia ixx="1.794e-7" ixy="-1.240e-5" ixz="1.91701e-8" iyy="1.5e-7" iyz="3.169e-6" izz="1.933e-7"/>
    </inertial>
    <visual name="">
      <origin rpy="0.0 0.0 0.0" xyz="0.0 0.0 0.0"/>
      <geometry>
        <mesh filename="package://reachy_description/meshes/antenna.dae"/>
      </geometry>
    </visual>
    <collision>
      <origin rpy="0.0 0 0.0" xyz="0.1 0.0 0.1"/>
      <geometry>
        <cylinder length="0.0" radius="0.0"/>
      </geometry>
    </collision>
  </link>
  <link name="r_antenna">
    <inertial>
      <origin rpy="0.0 0.0 0.0" xyz="-0.001 0.0 0.008"/>
      <mass value="0.004"/>
      <inertia ixx="1.794e-7" ixy="-1.240e-5" ixz="1.91701e-8" iyy="1.5e-7" iyz="3.169e-6" izz="1.933e-7"/>
    </inertial>
    <visual name="">
      <origin rpy="0.0 0.0 0.0" xyz="0.0 0.0 0.0"/>
      <geometry>
        <mesh filename="package://reachy_description/meshes/antenna.dae"/>
      </geometry>
    </visual>
    <collision>
      <origin rpy="0.0 0.0 0.0" xyz="0.0 0.0 0.0"/>
      <geometry>
        <cylinder length="0.0" radius="0.0"/>
      </geometry>
    </collision>
  </link>
  <!-- Right Arm Links -->
  <link name="r_shoulder">
    <inertial>
      <origin rpy="1.57 1.57 0.0" xyz="-0.016 0.036 0.0"/>
      <mass value="0.053"/>
      <inertia ixx="3.308e-4" ixy="9.972e-8" ixz="-2.037e-9" iyy="4.650e-5" iyz="2.113e-6" izz="3.545e-5"/>
    </inertial>
    <visual name="">
      <origin rpy="1.57 1.57 0.0" xyz="0.0 0.04 0.0"/>
      <geometry>
        <mesh filename="package://reachy_description/meshes/shoulder.dae"/>
      </geometry>
    </visual>
    <collision>
      <origin rpy="1.57 1.57 0.0" xyz="0.0 0.04 0.0"/>
      <geometry>
        <cylinder length="0.09" radius="0.035"/>
      </geometry>
    </collision>
  </link>
  <link name="r_shoulder_x">
    <inertial>
      <origin rpy="0.0 0.0 0.0" xyz="-0.0 0.0 -0.019"/>
      <mass value="0.158"/>
      <inertia ixx="6.887e+4" ixy="5.393e+0" ixz="-9.155e+2" iyy="7.895e+4" iyz="4.512e-1" izz="4.235e+4"/>
    </inertial>
    <visual name="">
      <origin rpy="0.0 0.0 0.0" xyz="0.0 0.0 0.0"/>
      <geometry>
        <mesh filename="package://reachy_description/meshes/shoulder_x.dae"/>
      </geometry>
    </visual>
    <collision>
      <origin rpy="0.0 0.0 0.0" xyz="0 0 -0.02"/>
      <geometry>
        <cylinder length="0.04" radius="0.035"/>
      </geometry>
    </collision>
  </link>
  <link name="r_upper_arm">
    <inertial>
      <origin rpy="0.0 0.0 0.0" xyz="-0.004 0.0 -0.1426"/>
      <mass value="0.430"/>
      <inertia ixx="3.264e-3" ixy="-4.027e-8" ixz="1.395e-4" iyy="3.345e-3" iyz="1.885e-6" izz="2.616e-4"/>
    </inertial>
    <visual name="">
      <origin rpy="0.0 0.0 0.0" xyz="0.0 0.0 -0.0526"/>
      <geometry>
        <mesh filename="package://reachy_description/meshes/upper_arm.dae"/>
      </geometry>
    </visual>
    <collision>
      <origin rpy="0.0 0.0 0.0" xyz="0.0 0.0 -0.16"/>
      <geometry>
        <cylinder length="0.25" radius="0.04"/>
      </geometry>
    </collision>
  </link>
  <link name="r_forearm">
    <inertial>
      <origin rpy="0.0 0.0 0.0" xyz="-0.008 0.0 -0.058"/>
      <mass value="0.162"/>
      <inertia ixx="2.532e-4" ixy="-2.999e-8" ixz="1.448e-5" iyy="2.538e-4" iyz="-4.323e-8" izz="1.234e-4"/>
    </inertial>
    <visual name="">
      <origin rpy="0.0 0.0 0.0" xyz="0.0 0.0 0.0"/>
      <geometry>
        <mesh filename="package://reachy_description/meshes/forearm.dae"/>
      </geometry>
    </visual>
    <collision>
      <origin rpy="0.0 0.0 0.0" xyz="0.0 0.0 -0.058"/>
      <geometry>
        <cylinder length="0.09" radius="0.04"/>
      </geometry>
    </collision>
  </link>
  <link name="r_wrist">
    <inertial>
      <origin rpy="0.0 0.0 0.0" xyz="0.0 0.0 -0.193"/>
      <mass value="0.197"/>
      <inertia ixx="6.157e-4" ixy="5.706e-8" ixz="-1.045e-5" iyy="6.280e-4" iyz="4.862e-7" izz="1.050e-4"/>
    </inertial>
    <visual name="">
      <origin rpy="0.0 0.0 0.0" xyz="0.0 0.0 -0.100"/>
      <geometry>
        <mesh filename="package://reachy_description/meshes/wrist.dae"/>
      </geometry>
    </visual>
    <collision>
      <origin rpy="0.0 0.0 0.0" xyz="0.0 0.0 -0.18"/>
      <geometry>
        <cylinder length="0.14" radius="0.035"/>
      </geometry>
    </collision>
  </link>
  <link name="r_wrist2hand">
    <inertial>
      <origin rpy="0.0 0.0 0.0" xyz="0.0 0.0 0.014"/>
      <mass value="0.01"/>
      <inertia ixx="6.750e-6" ixy="3.732e-11" ixz="-1.581e-11" iyy="6.060e-6" iyz="-1.746e-12" izz="5.774e-6"/>
    </inertial>
    <visual name="">
      <origin rpy="0.0 0.0 0.0" xyz="0.0 0.0 0.0"/>
      <geometry>
        <mesh filename="package://reachy_description/meshes/wrist2hand.dae"/>
      </geometry>
    </visual>
    <collision>
      <origin rpy="0.0 0.0 0.0" xyz="0.0 0.0 -0.03"/>
      <geometry>
        <cylinder length="0.06" radius="0.03"/>
      </geometry>
    </collision>
  </link>
  <link name="r_gripper_thumb">
    <inertial>
      <origin rpy="0.0 1.57 0.0" xyz="0.032 -0.008 0.0"/>
      <mass value="0.173"/>
      <inertia ixx="1.083e-4" ixy="-3.476e-5" ixz="1.331e-6" iyy="1.421e-4" iyz="6.730e-7" izz="2.112e-4"/>
    </inertial>
    <visual name="">
      <origin rpy="0.0 1.57 0.0" xyz="0.0 0.0 0.0"/>
      <geometry>
        <mesh filename="package://reachy_description/meshes/r_gripper_thumb.dae"/>
      </geometry>
    </visual>
    <collision>
      <origin rpy="0.0 1.57 0.0" xyz="0.0 0.02 -0.06"/>
      <geometry>
        <box size="0.1 0.012 0.035"/>
      </geometry>
    </collision>
  </link>
  <link name="r_gripper_finger">
    <inertial>
      <origin rpy="0.0 1.57 0.0" xyz="-0.005 -0.043 -0.0"/>
      <mass value="0.035"/>
      <inertia ixx="9.166e-5" ixy="-6.559e-6" ixz="-3.952e-8" iyy="1.062e-5" iyz="5.276e-9" izz="8.704e-5"/>
    </inertial>
    <visual name="">
      <origin rpy="0.0 1.57 0.0" xyz="0.0 0.0 0.0"/>
      <geometry>
        <mesh filename="package://reachy_description/meshes/r_gripper_finger.dae"/>
      </geometry>
    </visual>
    <collision>
      <origin rpy="0.0 1.57 0.0" xyz="0.0 -0.01 -0.02"/>
      <geometry>
        <box size="0.1 0.012 0.035"/>
      </geometry>
    </collision>
  </link>
  <link name="right_tip"/>
  <!-- Left Arm Links -->
  <link name="l_shoulder">
    <inertial>
      <origin rpy="-1.57 1.57 0.0" xyz="-0.016 0.044 0.0"/>
      <mass value="0.053"/>
      <inertia ixx="3.308e-4" ixy="9.972e-8" ixz="-2.037e-9" iyy="4.650e-5" iyz="2.113e-6" izz="3.545e-5"/>
    </inertial>
    <visual name="">
      <origin rpy="-1.57 1.57 0.0" xyz="0.0 -0.04 0.0"/>
      <geometry>
        <mesh filename="package://reachy_description/meshes/shoulder.dae"/>
      </geometry>
    </visual>
    <collision>
      <origin rpy="-1.57 1.57 0.0" xyz="0.0 -0.04 0.0"/>
      <geometry>
        <cylinder length="0.09" radius="0.035"/>
      </geometry>
    </collision>
  </link>
  <link name="l_shoulder_x">
    <inertial>
      <origin rpy="0.0 0.0 0.0" xyz="0.0 0.0 -0.019"/>
      <mass value="0.158"/>
      <inertia ixx="6.887e+4" ixy="5.393e+0" ixz="-9.155e+2" iyy="7.895e+4" iyz="4.512e-1" izz="4.235e+4"/>
    </inertial>
    <visual name="">
      <origin rpy="0.0 0.0 0.0" xyz="0.0 0.0 0.0"/>
      <geometry>
        <mesh filename="package://reachy_description/meshes/shoulder_x.dae"/>
      </geometry>
    </visual>
    <collision>
      <origin rpy="0.0 0.0 0.0" xyz="0 0 -0.02"/>
      <geometry>
        <cylinder length="0.04" radius="0.035"/>
      </geometry>
    </collision>
  </link>
  <link name="l_upper_arm">
    <inertial>
      <origin rpy="0.0 0.0 0.0" xyz="-0.004 0.0 -0.1426"/>
      <mass value="0.430"/>
      <inertia ixx="3.264e-3" ixy="-4.027e-8" ixz="1.395e-4" iyy="3.345e-3" iyz="1.885e-6" izz="2.616e-4"/>
    </inertial>
    <visual name="">
      <origin rpy="0.0 0.0 0.0" xyz="0.0 0.0 -0.0526"/>
      <geometry>
        <mesh filename="package://reachy_description/meshes/upper_arm.dae"/>
      </geometry>
    </visual>
    <collision>
      <origin rpy="0.0 0.0 0.0" xyz="0.0 0.0 -0.16"/>
      <geometry>
        <cylinder length="0.25" radius="0.04"/>
      </geometry>
    </collision>
  </link>
  <link name="l_forearm">
    <inertial>
      <origin rpy="0.0 0.0 0.0" xyz="-0.008 0.0 -0.058"/>
      <mass value="0.162"/>
      <inertia ixx="2.532e-4" ixy="-2.999e-8" ixz="1.448e-5" iyy="2.538e-4" iyz="-4.323e-8" izz="1.234e-4"/>
    </inertial>
    <visual name="">
      <origin rpy="0.0 0.0 0.0" xyz="0.0 0.0 0.0"/>
      <geometry>
        <mesh filename="package://reachy_description/meshes/forearm.dae"/>
      </geometry>
    </visual>
    <collision>
      <origin rpy="0.0 0.0 0.0" xyz="0.0 0.0 -0.058"/>
      <geometry>
        <cylinder length="0.09" radius="0.04"/>
      </geometry>
    </collision>
  </link>
  <link name="l_wrist">
    <inertial>
      <origin rpy="0.0 0.0 0.0" xyz="0.0 0.0 -0.193"/>
      <mass value="0.197"/>
      <inertia ixx="6.157e-4" ixy="5.706e-8" ixz="-1.045e-5" iyy="6.280e-4" iyz="4.862e-7" izz="1.050e-4"/>
    </inertial>
    <visual name="">
      <origin rpy="0.0 0.0 0.0" xyz="0.0 0.0 -0.1"/>
      <geometry>
        <mesh filename="package://reachy_description/meshes/wrist.dae"/>
      </geometry>
    </visual>
    <collision>
      <origin rpy="0.0 0.0 0.0" xyz="0.0 0.0 -0.18"/>
      <geometry>
        <cylinder length="0.14" radius="0.035"/>
      </geometry>
    </collision>
  </link>
  <link name="l_wrist2hand">
    <inertial>
      <origin rpy="0.0 0.0 0.0" xyz="0.0 0.0 0.014"/>
      <mass value="0.01"/>
      <inertia ixx="6.750e-6" ixy="3.732e-11" ixz="-1.581e-11" iyy="6.060e-6" iyz="-1.746e-12" izz="5.774e-6"/>
    </inertial>
    <visual name="">
      <origin rpy="0.0 0.0 0.0" xyz="0.0 0.0 0.0"/>
      <geometry>
        <mesh filename="package://reachy_description/meshes/wrist2hand.dae"/>
      </geometry>
    </visual>
    <collision>
      <origin rpy="0.0 0.0 0.0" xyz="0.0 0.0 -0.03"/>
      <geometry>
        <cylinder length="0.06" radius="0.03"/>
      </geometry>
    </collision>
  </link>
  <link name="l_gripper_thumb">
    <inertial>
      <origin rpy="0.0 1.57 0.0" xyz="0.032 0.008 0.0"/>
      <mass value="0.173"/>
      <inertia ixx="1.088e+5" ixy="3.479e+4" ixz="1.357e+3" iyy="1.422e+5" iyz="-7.930e+2" izz="2.116e+5"/>
    </inertial>
    <visual name="">
      <origin rpy="0.0 1.57 0.0" xyz="0.0 0.0 0.0"/>
      <geometry>
        <mesh filename="package://reachy_description/meshes/l_gripper_thumb.dae"/>
      </geometry>
    </visual>
    <collision>
      <origin rpy="0.0 1.57 0.0" xyz="0.0 -0.02 -0.06"/>
      <geometry>
        <box size="0.1 0.012 0.035"/>
      </geometry>
    </collision>
  </link>
  <link name="l_gripper_finger">
    <inertial>
      <origin rpy="0.0 1.57 0.0" xyz="0.005 -0.043 0.0"/>
      <mass value="0.035"/>
      <inertia ixx="9.165e-5" ixy="6.559e-6" ixz="3.609e-10" iyy="1.062e-5" iyz="4.666e-9" izz="8.705e-5"/>
    </inertial>
    <visual name="">
      <origin rpy="0.0 1.57 0.0" xyz="0.0 0.0 0.0"/>
      <geometry>
        <mesh filename="package://reachy_description/meshes/l_gripper_finger.dae"/>
      </geometry>
    </visual>
    <collision>
      <origin rpy="0.0 1.57 0.0" xyz="0.0 0.01 -0.02"/>
      <geometry>
        <box size="0.1 0.012 0.035"/>
      </geometry>
    </collision>
  </link>
  <link name="left_tip"/>
  <!-- Head and Torso joints -->
  <joint name="pedestal" type="fixed">
    <origin rpy="0 0 0" xyz="0 0 0.325"/>
    <parent link="pedestal"/>
    <child link="torso"/>
  </joint>
  <joint name="r_antenna" type="revolute">
    <origin rpy="-0.166 -1.054 1.11" xyz="-0.052 -0.057 0.086"/>
    <parent link="head"/>
    <child link="r_antenna"/>
    <axis xyz="0 0 1"/>
    <limit effort="10." lower="-2.618" upper="2.618" velocity="0.0"/>
  </joint>
  <joint name="l_antenna" type="revolute">
    <origin rpy="0.166 -1.054 -1.11" xyz="-0.052 0.057 0.086"/>
    <parent link="head"/>
    <child link="l_antenna"/>
    <axis xyz="0 0 1"/>
    <limit effort="10." lower="-2.618" upper="2.618" velocity="0.0"/>
  </joint>
  <!-- Right Arm joint -->
  <joint name="r_shoulder_pitch" type="revolute">
    <origin rpy="0.0 0.0 0.0" xyz="0.0 -0.19 0.0"/>
    <parent link="torso"/>
    <child link="r_shoulder"/>
    <axis xyz="0 1 0"/>
    <limit effort="10." lower="-2.618" upper="1.57" velocity="0.0"/>
  </joint>
  <joint name="r_shoulder_roll" type="revolute">
    <origin rpy="0.0 0.0 0.0" xyz="0 0 0"/>
    <parent link="r_shoulder"/>
    <child link="r_shoulder_x"/>
    <axis xyz="1 0 0"/>
    <limit effort="10." lower="-3.14" upper="0.174" velocity="0.0"/>
  </joint>
  <joint name="r_arm_yaw" type="revolute">
    <origin rpy="0.0 0.0 0.0" xyz="0 0 0"/>
    <parent link="r_shoulder_x"/>
    <child link="r_upper_arm"/>
    <axis xyz="0 0 1"/>
    <limit effort="10." lower="-1.57" upper="1.57" velocity="0.0"/>
  </joint>
  <joint name="r_elbow_pitch" type="revolute">
    <origin rpy="0.0 0.0 0.0" xyz="0 0 -0.28"/>
    <parent link="r_upper_arm"/>
    <child link="r_forearm"/>
    <axis xyz="0 1 0"/>
    <limit effort="10." lower="-2.182" upper="0" velocity="0.0"/>
  </joint>
  <joint name="r_forearm_yaw" type="revolute">
    <origin rpy="0.0 0.0 0.0" xyz="0 0 0"/>
    <parent link="r_forearm"/>
    <child link="r_wrist"/>
    <axis xyz="0 0 1"/>
    <limit effort="10." lower="-1.745" upper="1.745" velocity="0.0"/>
  </joint>
  <joint name="r_wrist_pitch" type="revolute">
    <origin rpy="0.0 0.0 0.0" xyz="0 0 -0.25"/>
    <parent link="r_wrist"/>
    <child link="r_wrist2hand"/>
    <axis xyz="0 1 0"/>
    <limit effort="10." lower="-0.785" upper="0.785" velocity="0.0"/>
  </joint>
  <joint name="r_wrist_roll" type="revolute">
    <origin rpy="0.0 0.0 0.0" xyz="0 0 -0.0325"/>
    <parent link="r_wrist2hand"/>
    <child link="r_gripper_thumb"/>
    <axis xyz="1 0 0"/>
    <limit effort="10." lower="-0.785" upper="0.785" velocity="0.0"/>
  </joint>
  <joint name="r_gripper" type="revolute">
    <origin rpy="0.0 0.0 0.0" xyz="0.0 -0.037 -0.03998"/>
    <parent link="r_gripper_thumb"/>
    <child link="r_gripper_finger"/>
    <axis xyz="1 0 0"/>
    <limit effort="10." lower="-1.2" upper="0.35" velocity="0.0"/>
  </joint>
  <joint name="r_tip" type="fixed">
    <origin rpy="0 0 0" xyz="0 -0.012 -0.085"/>
    <parent link="r_gripper_thumb"/>
    <child link="right_tip"/>
  </joint>
  <joint name="l_shoulder_pitch" type="revolute">
    <origin rpy="0.0 0.0 0.0" xyz="0.0 0.19 0.0"/>
    <parent link="torso"/>
    <child link="l_shoulder"/>
    <axis xyz="0 1 0"/>
    <limit effort="10." lower="-2.618" upper="1.57" velocity="0.0"/>
  </joint>
  <joint name="l_shoulder_roll" type="revolute">
    <origin rpy="0.0 0.0 0.0" xyz="0 0 0"/>
    <parent link="l_shoulder"/>
    <child link="l_shoulder_x"/>
    <axis xyz="1 0 0"/>
    <limit effort="10." lower="-0.174" upper="3.14" velocity="0.0"/>
  </joint>
  <joint name="l_arm_yaw" type="revolute">
    <origin rpy="0.0 0.0 0.0" xyz="0 0 0"/>
    <parent link="l_shoulder_x"/>
    <child link="l_upper_arm"/>
    <axis xyz="0 0 1"/>
    <limit effort="10." lower="-1.57" upper="1.57" velocity="0.0"/>
  </joint>
  <joint name="l_elbow_pitch" type="revolute">
    <origin rpy="0.0 0.0 0.0" xyz="0 0 -0.28"/>
    <parent link="l_upper_arm"/>
    <child link="l_forearm"/>
    <axis xyz="0 1 0"/>
    <limit effort="10." lower="-2.182" upper="0" velocity="0.0"/>
  </joint>
  <joint name="l_forearm_yaw" type="revolute">
    <origin rpy="0.0 0.0 0.0" xyz="0 0 0"/>
    <parent link="l_forearm"/>
    <child link="l_wrist"/>
    <axis xyz="0 0 1"/>
    <limit effort="10." lower="-1.745" upper="1.745" velocity="0.0"/>
  </joint>
  <joint name="l_wrist_pitch" type="revolute">
    <origin rpy="0.0 0.0 0.0" xyz="0 0 -0.25"/>
    <parent link="l_wrist"/>
    <child link="l_wrist2hand"/>
    <axis xyz="0 1 0"/>
    <limit effort="10." lower="-0.785" upper="0.785" velocity="0.0"/>
  </joint>
  <joint name="l_wrist_roll" type="revolute">
    <origin rpy="0.0 0.0 0.0" xyz="0 0 -0.0325"/>
    <parent link="l_wrist2hand"/>
    <child link="l_gripper_thumb"/>
    <axis xyz="1 0 0"/>
    <limit effort="10." lower="-0.785" upper="0.785" velocity="0.0"/>
  </joint>
  <joint name="l_gripper" type="revolute">
    <origin rpy="0.0 0.0 0.0" xyz="0.0 0.037 -0.03998"/>
    <parent link="l_gripper_thumb"/>
    <child link="l_gripper_finger"/>
    <axis xyz="1 0 0"/>
    <limit effort="10." lower="-0.35" upper="1.2" velocity="0.0"/>
  </joint>
  <joint name="l_tip" type="fixed">
    <origin rpy="0 0 0" xyz="0 0.012 -0.085"/>
    <parent link="l_gripper_thumb"/>
    <child link="left_tip"/>
  </joint>
  <!-- Head joint... -->
  <!-- ...with a fixed joint -->
  <!--
<joint name="torso2head" type="fixed">
    <origin xyz="0.015 0.0 0.095" rpy="0 0.174 0" />
    <parent link="torso" />
    <child link="head" />
</joint>
-->
  <joint name="orbita_roll" type="revolute">
    <origin rpy="0 0.174 0" xyz="0.015 0.0 0.095"/>
    <parent link="torso"/>
    <child link="head_x"/>
    <axis xyz="1 0 0"/>
    <limit effort="10." lower="-0.8" upper="0.8" velocity="0.0"/>
  </joint>
  <link name="head_x"/>
  <joint name="orbita_pitch" type="revolute">
    <origin rpy="0.0 0.0 0.0" xyz="0 0 0"/>
    <parent link="head_x"/>
    <child link="head_y"/>
    <axis xyz="0 1 0"/>
    <limit effort="10." lower="-0.8" upper="1.13" velocity="0.0"/>
  </joint>
  <link name="head_y"/>
  <joint name="orbita_yaw" type="revolute">
    <origin rpy="0.0 0.0 0.0" xyz="0 0 0"/>
    <parent link="head_y"/>
    <child link="head_z"/>
    <axis xyz="0 0 1"/>
    <limit effort="10." lower="-2.79" upper="2.79" velocity="0.0"/>
  </joint>
  <link name="head_z"/>
  <joint name="orbita_fixed" type="fixed">
    <origin rpy="0.0 0.0 0.0" xyz="0 0 0"/>
    <parent link="head_z"/>
    <child link="head"/>
  </joint>
  <!-- Fixed Orbita Arms Visuals -->
  <joint name="orbita_top" type="fixed">
    <origin rpy="0 0.174 0" xyz="0.0067 0.0 0.0478"/>
    <parent link="torso"/>
    <child link="top_orbita_arm"/>
  </joint>
  <link name="top_orbita_arm">
    <visual name="">
      <origin rpy="0.0 0.0 0.5236" xyz="0.0 0.0 0.0"/>
      <geometry>
        <mesh filename="package://reachy_description/meshes/orbita_arm.dae"/>
      </geometry>
    </visual>
    <collision>
      <origin rpy="0.0 0.0 0.0" xyz="0.0 0.0 0.0"/>
      <geometry>
        <cylinder length="0.0" radius="0.0"/>
      </geometry>
    </collision>
  </link>
  <joint name="orbita_middle" type="fixed">
    <origin rpy="0 0.174 0" xyz="0.0067 0.0 0.0478"/>
    <parent link="torso"/>
    <child link="middle_orbita_arm"/>
  </joint>
  <link name="middle_orbita_arm">
    <visual name="">
      <origin rpy="0.0 0.0 2.618" xyz="0.0 0.0 0.0"/>
      <geometry>
        <mesh filename="package://reachy_description/meshes/orbita_arm.dae"/>
      </geometry>
    </visual>
    <collision>
      <origin rpy="0.0 0.0 0.0" xyz="0.0 0.0 0.0"/>
      <geometry>
        <cylinder length="0.0" radius="0.0"/>
      </geometry>
    </collision>
  </link>
  <joint name="orbita_bottom" type="fixed">
    <origin rpy="0 0.174 0" xyz="0.0067 0.0 0.0478"/>
    <parent link="torso"/>
    <child link="bottom_orbita_arm"/>
  </joint>
  <link name="bottom_orbita_arm">
    <visual name="">
      <origin rpy="0.0 0.0 -1.57" xyz="0.0 0.0 0.0"/>
      <geometry>
        <mesh filename="package://reachy_description/meshes/orbita_arm.dae"/>
      </geometry>
    </visual>
    <collision>
      <origin rpy="0.0 0.0 0.0" xyz="0.0 0.0 0.0"/>
      <geometry>
        <cylinder length="0.0" radius="0.0"/>
      </geometry>
    </collision>
  </link>
  <joint name="left_cam_fixed" type="fixed">
    <origin rpy="0.0 0.0 0.0" xyz="0.0033 0.03625 0.061"/>
    <parent link="head"/>
    <child link="left_camera"/>
  </joint>
  <link name="left_camera"/>
  <joint name="right_cam_fixed" type="fixed">
    <origin rpy="0.0 0.0 0.0" xyz="0.0033 -0.03625 0.061"/>
    <parent link="head"/>
    <child link="right_camera"/>
  </joint>
  <link name="right_camera"/>
</robot>

